Workbook

Sheet Predpoklady
A1: Předpoklady — rozpočet LLM · Důkazní materiál 1930
A2: JEDINÝ list k editaci. Modrý text = zadaná hodnota, černý = vzorec, žluté podbarvení = klíčová páka. Zdroj všech čísel: technika/llm-rozpocet-2026-07-28.md (operations-economics, 2026-07-28).
A4: Kód | B4: Předpoklad | C4: Hodnota | D4: Jednotka | E4: Jistota | F4: Zdroj / poznámka
A5: P-1 | B5: Ceník poskytovatele (USD / 1M tokenů) | C5: viz list Cenik | D5: USD/1M tok. | E5: Ověřeno | F5: skill claude-api, 2026-07-28 — POSKYTOVATEL-SPECIFICKÉ
A6: P-2 | B6: Český tokenizační multiplikátor | C6: 2.5 | D6: znaků / token | E6: Odhad | F6: §3; citlivost na listu Citlivost_tokenizer. Ověřit přes messages.count_tokens.
A7: P-3 | B7: Délka systémového promptu | C7: 1716 | D7: znaků | E7: Změřeno | F7: prompty/protokol.md v0.3, ř. 12–38
A8: P-4 | B8: Délka šablony formátu vstupu | C8: 715 | D8: znaků | E8: Změřeno | F8: prompty/protokol.md v0.3, ř. 44–56
A9: P-5 | B9: Délka per-uzlové instance vstupu | C9: 1234 | D9: znaků | E9: Změřeno | F9: instance farmar-brod proti obsah/*.yaml a rules.js (§2.1)
A10: P-6 | B10: Délka výstupu (protokol 3–5 vět) | C10: 518 | D10: znaků | E10: Změřeno | F10: kanonická ukázka v prompty/protokol.md
A11: P-7 | B11: Volání na run (1p–4p) | C11: viz detail ř. 24–32 | D11: volání / run | E11: Změřeno | F11: simulátor prototyp/sim/run.js, 2 000 runů na počet hráčů, strategie kompetentni
A12: P-8 | B12: Podíl zmařených volání (timeout 10 s, chyba, 529) | C12: 0.03 | D12: % volání | E12: Odhad | F12: rezerva na síťový ocas a přetížení; zmařené volání se platí celé
A13: P-9 | B13: Steam revenue share | C13: 0.3 | D13: % z ceny | E13: Ověřeno | F13: standard do $10M obratu
A14: P-10 | B14: DPH (CZ); cena 9,99 € je včetně DPH | C14: 0.21 | D14: % z ceny | E14: Ověřeno | F14: Steam v EU uvádí ceny s DPH; sazby v EU 17–27 % → ±4 % na čistý příjem
A15: P-11 | B15: Kurz EUR → USD | C15: 1.08 | D15: USD / EUR | E15: Odhad | F15: vliv lineární a malý
A16: P-12 | B16: Rozdělení runů na hráče | C16: viz detail ř. 36–39 | D16: runů / hráč | E16: Odhad | F16: žádná data; NEJKŘEHČÍ předpoklad celého modelu (§10)
A17: P-13 | B17: Cache hit-rate (aplikační cache protokolů) | C17: 0.6 | D17: % volání | E17: Volný parametr | F17: §6 — neodhaduje se, je to páka. Default 0,60 dle §7 (předgenerování).
A18: P-14 | B18: Fixní infrastruktura (proxy + cache DB) | C18: 50–150 | D18: $ / měsíc | E18: Odhad | F18: Cloudflare Workers + KV/D1 nebo malá VPS; pokryto 8 prodanými kopiemi měsíčně
A19: P-15 | B19: Free demo — API náklady | C19: 0 | D19: $ | E19: Ověřeno | F19: design §9: pevný sólo run s předgenerovaným obsahem
A22: Detail P-7 — volání na run (změřeno simulátorem, 2 000 runů na počet hráčů; §4 reportu)
A23: Složka | B23: 1 hráč | C23: 2 hráči | D23: 3 hráči | E23: 4 hráči
A24: z toho backbone | B24: 4.5 | C24: 4.83 | D24: 5.03 | E24: 5.07
A25: z toho Zátah | B25: 1.14 | C25: 0.99 | D25: 0.99 | E25: 0.99
A26: z toho léčka | B26: 1 | C26: 1.44 | D26: 1.42 | E26: 1.42
A27: z toho konfrontace | B27: 0.92 | C27: 1.29 | D27: 1.19 | E27: 1.19
A28: Volání na run celkem [P-7] | B28: 7.56 | C28: 8.54 | D28: 8.63 | E28: 8.66
A29: Součet složek (kontrola zaokrouhlení proti [P-7]) | B29: =SUM(B24:B27) -> 7.56 | C29: =SUM(C24:C27) -> 8.55 | D29: =SUM(D24:D27) -> 8.63 | E29: =SUM(E24:E27) -> 8.67
A30: pocet_uzlu v run_end (diagnostika — NENÍ počet volání, nález C) | B30: 6.36 | C30: 6.41 | D30: 6.63 | E30: 6.67
A31: medián volání na run | B31: 8 | C31: 9 | D31: 9 | E31: 9
A32: p90 volání na run | B32: 11 | C32: 11 | D32: 11 | E32: 11
A34: Detail P-12 — rozdělení runů na hráče (odhad; kalibrace 40 % ≤2 runy · 40 % 3–15 · 15 % 16–80 · 5 % >80, μ=200)
A35: Typ hráče | B35: Runů na hráče | C35: Poznámka
A36: medián | B36: 6 | C36: polovina populace odehraje méně
A37: heavy | B37: 100 | C37: pásmo 15 % populace (16–80 runů) a výš
A38: extrém | B38: 500 | C38: ocas ~5 % populace (>80 runů)
A39: populační průměr | B39: 19.8 | C39: vážený průměr kalibrace — základ pro $/hráč a marži
A41: Příjmová strana — čistý příjem z jedné licence (§8.1)
A42: Položka | C42: Hodnota | D42: Jednotka | F42: Poznámka
A43: Hrubá cena na Steamu (včetně DPH) | C43: 9.99 | D43: € | F43: zadaná cena titulu
A44: DPH [P-10] | C44: =C14 -> 0.21 | D44: % | F44: odkaz na P-10
A45: Steam revenue share [P-9] | C45: =C13 -> 0.3 | D45: % | F45: odkaz na P-9
...

Sheet Cenik
A1: Ceník modelů [P-1] — POSKYTOVATEL-SPECIFICKÉ
A2: Při změně poskytovatele se mění POUZE tento list; zbytek modelu se přepočítá sám. Ceny ověřeny skillem claude-api 2026-07-28 (§10, §13).
A4: Model | B4: $ / M vstupních tokenů | C4: $ / M výstupních tokenů | D4: Poznámka (poskytovatel-specifická)
A5: Claude Haiku 4.5 | B5: 1 | C5: 5 | D5: Anthropic 1P API. Minimální cachovatelný prefix 4 096 tok. — náš prefix 972 tok. se necachuje (tiše). Prompt caching se nevyplatí (§5).
A6: Claude Sonnet 5 (std) | B6: 3 | C6: 15 | D6: Anthropic 1P API. Minimální prefix 1 024 tok. — chybí 52 tokenů (nález D). Cache read 0,1×, write 1,25×, TTL 5 min.
A7: Claude Sonnet 5 (zaváděcí do 2026-08-31) | B7: 2 | C7: 10 | D7: Anthropic 1P API, dočasná zaváděcí cena. Po 2026-08-31 platí std sazba.
A8: Claude Opus 5 | B8: 5 | C8: 25 | D8: Anthropic 1P API. Minimální prefix 512 tok. — náš prefix by se cachoval. Referenční horní mez.
A9: třída Flash-Lite (referenční konkurence) | B9: 0.1 | C9: 0.4 | D9: JINÝ poskytovatel (třída Gemini 2.5 Flash-Lite, ověřeno WebSearch 2026-07-28). Jiná tokenizace (±20 %), jiné cache násobky i batch sleva.
A11: Poskytovatel-agnostické je naopak: volání na run [P-7], délky promptu [P-3..P-6], struktura break-even a čistý příjem, klíčový prostor cache (§10).

Sheet Naklad_volani
A1: Náklad na jedno volání (§2)
A2: Tokeny = ROUND(znaků / P-2; 0) — tokeny jsou celá čísla. Vše odkazuje na list Predpoklady a Cenik; na tomto listu není žádná zadaná hodnota.
A4: Část promptu | B4: Znaků | C4: Tokenů | D4: Ekonomické chování
A5: Systémový prompt [P-3] | B5: =Predpoklady!$C$7 -> 1716 | C5: =ROUND(B5/Predpoklady!$C$6,0) -> 686 | D5: neměnný — identický ve všech voláních
A6: Šablona formátu vstupu [P-4] | B6: =Predpoklady!$C$8 -> 715 | C6: =ROUND(B6/Predpoklady!$C$6,0) -> 286 | D6: neměnná
A7: Stabilní prefix celkem | B7: =B5+B6 -> 2431 | C7: =ROUND(B7/Predpoklady!$C$6,0) -> 972 | D7: cachovatelný (§5) — 972 tok.
A8: Instance uzlu [P-5] | B8: =Predpoklady!$C$9 -> 1234 | C8: =ROUND(B8/Predpoklady!$C$6,0) -> 494 | D8: mění se per uzel
A9: Vstup celkem | B9: =B7+B8 -> 3665 | C9: =ROUND(B9/Predpoklady!$C$6,0) -> 1466 | D9: architektura §2.3 uváděla 600–800 tok. (nález A)
A10: Výstup [P-6] | B10: =Predpoklady!$C$10 -> 518 | C10: =ROUND(B10/Predpoklady!$C$6,0) -> 207 | D10: prompt caching se ho nikdy nedotkne (nález B)
A12: Cena za jedno volání podle modelu (§2.2)
A13: Model | B13: $ / M vstup | C13: $ / M výstup | D13: Cena vstupu ($) | E13: Cena výstupu ($) | F13: CENA ZA VOLÁNÍ ($)
A14: =Cenik!A5 -> Claude Haiku 4.5 | B14: =Cenik!B5 -> 1 | C14: =Cenik!C5 -> 5 | D14: =$C$9/1000000*B14 -> 0.001466 | E14: =$C$10/1000000*C14 -> 0.001035 | F14: =D14+E14 -> 0.002501
A15: =Cenik!A6 -> Claude Sonnet 5 (std) | B15: =Cenik!B6 -> 3 | C15: =Cenik!C6 -> 15 | D15: =$C$9/1000000*B15 -> 0.004398 | E15: =$C$10/1000000*C15 -> 0.003105 | F15: =D15+E15 -> 0.007503
A16: =Cenik!A7 -> Claude Sonnet 5 (zaváděcí do 2026-08-31) | B16: =Cenik!B7 -> 2 | C16: =Cenik!C7 -> 10 | D16: =$C$9/1000000*B16 -> 0.002932 | E16: =$C$10/1000000*C16 -> 0.00207 | F16: =D16+E16 -> 0.005002
A17: =Cenik!A8 -> Claude Opus 5 | B17: =Cenik!B8 -> 5 | C17: =Cenik!C8 -> 25 | D17: =$C$9/1000000*B17 -> 0.00733 | E17: =$C$10/1000000*C17 -> 0.005175 | F17: =D17+E17 -> 0.012505
A18: =Cenik!A9 -> třída Flash-Lite (referenční konkurence) | B18: =Cenik!B9 -> 0.1 | C18: =Cenik!C9 -> 0.4 | D18: =$C$9/1000000*B18 -> 0.0001466 | E18: =$C$10/1000000*C18 -> 8.28e-05 | F18: =D18+E18 -> 0.0002294
A20: Kontrola proti §2.2 reportu: Claude Haiku 4.5 = $0,002501 za volání. Výstup je 41 % ceny volání (nález B) — sráží ho jedině aplikační cache protokolů, ne prompt caching.

Sheet Citlivost_tokenizer
A1: Citlivost na českém tokenizeru [P-2] (§3)
A2: Jediný nezměřený vstup do ceny volání. Řádek se základem odkazuje přímo na P-2 — změna P-2 posune základ i odchylky.
A3: Znaků / token | B3: Vstup (tok.) | C3: Výstup (tok.) | D3: =Naklad_volani!$A$14 -> Claude Haiku 4.5 | E3: =Naklad_volani!$A$15 -> Claude Sonnet 5 (std) | F3: =Naklad_volani!$A$16 -> Claude Sonnet 5 (zaváděcí do 2026-08-31) | G3: =Naklad_volani!$A$17 -> Claude Opus 5 | H3: =Naklad_volani!$A$18 -> třída Flash-Lite (referenční konkurence) | I3: Odchylka od základu | J3: Poznámka
A4: 2.2 | B4: =ROUND((Predpoklady!$C$7+Predpoklady!$C$8+Predpoklady!$C$9)/$A4,0) -> 1666 | C4: =ROUND(Predpoklady!$C$10/$A4,0) -> 235 | D4: =$B4/1000000*Naklad_volani!$B$14+$C4/1000000*Naklad_volani!$C$14 -> 0.002841 | E4: =$B4/1000000*Naklad_volani!$B$15+$C4/1000000*Naklad_volani!$C$15 -> 0.008523 | F4: =$B4/1000000*Naklad_volani!$B$16+$C4/1000000*Naklad_volani!$C$16 -> 0.005682 | G4: =$B4/1000000*Naklad_volani!$B$17+$C4/1000000*Naklad_volani!$C$17 -> 0.014205 | H4: =$B4/1000000*Naklad_volani!$B$18+$C4/1000000*Naklad_volani!$C$18 -> 0.0002606 | I4: =D4/D$5-1 -> 0.13594562 | J4: pesimisticky
A5: =Predpoklady!$C$6 -> 2.5 | B5: =ROUND((Predpoklady!$C$7+Predpoklady!$C$8+Predpoklady!$C$9)/$A5,0) -> 1466 | C5: =ROUND(Predpoklady!$C$10/$A5,0) -> 207 | D5: =$B5/1000000*Naklad_volani!$B$14+$C5/1000000*Naklad_volani!$C$14 -> 0.002501 | E5: =$B5/1000000*Naklad_volani!$B$15+$C5/1000000*Naklad_volani!$C$15 -> 0.007503 | F5: =$B5/1000000*Naklad_volani!$B$16+$C5/1000000*Naklad_volani!$C$16 -> 0.005002 | G5: =$B5/1000000*Naklad_volani!$B$17+$C5/1000000*Naklad_volani!$C$17 -> 0.012505 | H5: =$B5/1000000*Naklad_volani!$B$18+$C5/1000000*Naklad_volani!$C$18 -> 0.0002294 | I5: =D5/D$5-1 -> 0 | J5: ZÁKLAD [P-2]
A6: 3 | B6: =ROUND((Predpoklady!$C$7+Predpoklady!$C$8+Predpoklady!$C$9)/$A6,0) -> 1222 | C6: =ROUND(Predpoklady!$C$10/$A6,0) -> 173 | D6: =$B6/1000000*Naklad_volani!$B$14+$C6/1000000*Naklad_volani!$C$14 -> 0.002087 | E6: =$B6/1000000*Naklad_volani!$B$15+$C6/1000000*Naklad_volani!$C$15 -> 0.006261 | F6: =$B6/1000000*Naklad_volani!$B$16+$C6/1000000*Naklad_volani!$C$16 -> 0.004174 | G6: =$B6/1000000*Naklad_volani!$B$17+$C6/1000000*Naklad_volani!$C$17 -> 0.010435 | H6: =$B6/1000000*Naklad_volani!$B$18+$C6/1000000*Naklad_volani!$C$18 -> 0.0001914 | I6: =D6/D$5-1 -> -0.16553379 | J6: optimisticky
A8: Závěr §3: tokenizer o ničem nerozhoduje — ±15 % na čísle, které je o dva řády pod čistým příjmem. Ověřit při stavbě adaptéru, ale nečekat s rozhodnutím.

Sheet Naklad_run
A1: Náklad na jeden run (§4)
A2: Efektivní volání = změřená volání × (1 + P-8). Zmařené volání (timeout, chyba, 529) se platí celé.
A3: Položka | B3: 1 hráč | C3: 2 hráči | D3: 3 hráči | E3: 4 hráči
A4: z toho backbone | B4: =Predpoklady!B24 -> 4.5 | C4: =Predpoklady!C24 -> 4.83 | D4: =Predpoklady!D24 -> 5.03 | E4: =Predpoklady!E24 -> 5.07
A5: z toho Zátah | B5: =Predpoklady!B25 -> 1.14 | C5: =Predpoklady!C25 -> 0.99 | D5: =Predpoklady!D25 -> 0.99 | E5: =Predpoklady!E25 -> 0.99
A6: z toho léčka | B6: =Predpoklady!B26 -> 1 | C6: =Predpoklady!C26 -> 1.44 | D6: =Predpoklady!D26 -> 1.42 | E6: =Predpoklady!E26 -> 1.42
A7: z toho konfrontace | B7: =Predpoklady!B27 -> 0.92 | C7: =Predpoklady!C27 -> 1.29 | D7: =Predpoklady!D27 -> 1.19 | E7: =Predpoklady!E27 -> 1.19
A8: Volání na run celkem [P-7] | B8: =Predpoklady!B28 -> 7.56 | C8: =Predpoklady!C28 -> 8.54 | D8: =Predpoklady!D28 -> 8.63 | E8: =Predpoklady!E28 -> 8.66
A9: Zmařená volání [P-8] | B9: =B8*Predpoklady!$C$12 -> 0.2268 | C9: =C8*Predpoklady!$C$12 -> 0.2562 | D9: =D8*Predpoklady!$C$12 -> 0.2589 | E9: =E8*Predpoklady!$C$12 -> 0.2598
A10: EFEKTIVNÍ VOLÁNÍ NA RUN | B10: =B8*(1+Predpoklady!$C$12) -> 7.7868 | C10: =C8*(1+Predpoklady!$C$12) -> 8.7962 | D10: =D8*(1+Predpoklady!$C$12) -> 8.8889 | E10: =E8*(1+Predpoklady!$C$12) -> 8.9198
A11: z toho finálové uzly (Zátah + léčka + konfrontace), efektivní | B11: =SUM(B5:B7)*(1+Predpoklady!$C$12) -> 3.1518 | C11: =SUM(C5:C7)*(1+Predpoklady!$C$12) -> 3.8316 | D11: =SUM(D5:D7)*(1+Predpoklady!$C$12) -> 3.708 | E11: =SUM(E5:E7)*(1+Predpoklady!$C$12) -> 3.708
A12: pocet_uzlu v run_end (diagnostika — NENÍ počet volání, nález C) | B12: =Predpoklady!B30 -> 6.36 | C12: =Predpoklady!C30 -> 6.41 | D12: =Predpoklady!D30 -> 6.63 | E12: =Predpoklady!E30 -> 6.67
A14: Matice: náklad na run bez cache ($) = efektivní volání × cena za volání
A15: Model | B15: 1 hráč | C15: 2 hráči | D15: 3 hráči | E15: 4 hráči
A16: =Naklad_volani!$A$14 -> Claude Haiku 4.5 | B16: =B$10*Naklad_volani!$F$14 -> 0.019474787 | C16: =C$10*Naklad_volani!$F$14 -> 0.021999296 | D16: =D$10*Naklad_volani!$F$14 -> 0.022231139 | E16: =E$10*Naklad_volani!$F$14 -> 0.02230842
A17: =Naklad_volani!$A$15 -> Claude Sonnet 5 (std) | B17: =B$10*Naklad_volani!$F$15 -> 0.05842436 | C17: =C$10*Naklad_volani!$F$15 -> 0.065997889 | D17: =D$10*Naklad_volani!$F$15 -> 0.066693417 | E17: =E$10*Naklad_volani!$F$15 -> 0.066925259
A18: =Naklad_volani!$A$16 -> Claude Sonnet 5 (zaváděcí do 2026-08-31) | B18: =B$10*Naklad_volani!$F$16 -> 0.038949574 | C18: =C$10*Naklad_volani!$F$16 -> 0.043998592 | D18: =D$10*Naklad_volani!$F$16 -> 0.044462278 | E18: =E$10*Naklad_volani!$F$16 -> 0.04461684
A19: =Naklad_volani!$A$17 -> Claude Opus 5 | B19: =B$10*Naklad_volani!$F$17 -> 0.097373934 | C19: =C$10*Naklad_volani!$F$17 -> 0.10999648 | D19: =D$10*Naklad_volani!$F$17 -> 0.11115569 | E19: =E$10*Naklad_volani!$F$17 -> 0.1115421
A20: =Naklad_volani!$A$18 -> třída Flash-Lite (referenční konkurence) | B20: =B$10*Naklad_volani!$F$18 -> 0.0017862919 | C20: =C$10*Naklad_volani!$F$18 -> 0.0020178483 | D20: =D$10*Naklad_volani!$F$18 -> 0.0020391137 | E20: =E$10*Naklad_volani!$F$18 -> 0.0020462021
A22: Hot-seat 4 hráčů jede z JEDNÉ zakoupené licence, ale generuje o 15 % víc volání než sólo — ekonomicky je horší než sólo. Model je proto konzervativně stavěn na sólo/hot-seat.
A23: Nález C: kdo počítá rozpočet z pocet_uzlu místo z volání (band_resolved), podstřelí ho o ~30 %.

Sheet Cache_krivka
A1: Křivka nákladu podle cache hit-rate (§6.1) — sólo run
A2: Hit = žádné volání → mizí vstup i výstup. náklad/run = efektivní volání × (1 − hit-rate) × cena volání. Break-even = čistý příjem na licenci / náklad na run.
A3: Cache hit-rate | B3: Haiku 4.5 — $ / run | C3: Haiku 4.5 — € / run | D3: Sonnet 5 std — $ / run | E3: Sonnet 5 std — € / run | F3: Break-even Haiku (runů) | G3: Break-even Sonnet 5 (runů)
A4: 0 | B4: =Naklad_run!$B$10*(1-$A4)*Naklad_volani!$F$14 -> 0.019474787 | C4: =B4/Predpoklady!$C$15 -> 0.01803221 | D4: =Naklad_run!$B$10*(1-$A4)*Naklad_volani!$F$15 -> 0.05842436 | E4: =D4/Predpoklady!$C$15 -> 0.05409663 | F4: =IFERROR(Predpoklady!$C$50/B4,"—") -> 320.50086 | G4: =IFERROR(Predpoklady!$C$50/D4,"—") -> 106.83362
A5: =A4+0.05 -> 0.05 | B5: =Naklad_run!$B$10*(1-$A5)*Naklad_volani!$F$14 -> 0.018501047 | C5: =B5/Predpoklady!$C$15 -> 0.017130599 | D5: =Naklad_run!$B$10*(1-$A5)*Naklad_volani!$F$15 -> 0.055503142 | E5: =D5/Predpoklady!$C$15 -> 0.051391798 | F5: =IFERROR(Predpoklady!$C$50/B5,"—") -> 337.36933 | G5: =IFERROR(Predpoklady!$C$50/D5,"—") -> 112.45644
A6: =A5+0.05 -> 0.1 | B6: =Naklad_run!$B$10*(1-$A6)*Naklad_volani!$F$14 -> 0.017527308 | C6: =B6/Predpoklady!$C$15 -> 0.016228989 | D6: =Naklad_run!$B$10*(1-$A6)*Naklad_volani!$F$15 -> 0.052581924 | E6: =D6/Predpoklady!$C$15 -> 0.048686967 | F6: =IFERROR(Predpoklady!$C$50/B6,"—") -> 356.11207 | G6: =IFERROR(Predpoklady!$C$50/D6,"—") -> 118.70402
A7: =A6+0.05 -> 0.15 | B7: =Naklad_run!$B$10*(1-$A7)*Naklad_volani!$F$14 -> 0.016553569 | C7: =B7/Predpoklady!$C$15 -> 0.015327378 | D7: =Naklad_run!$B$10*(1-$A7)*Naklad_volani!$F$15 -> 0.049660706 | E7: =D7/Predpoklady!$C$15 -> 0.045982135 | F7: =IFERROR(Predpoklady!$C$50/B7,"—") -> 377.05984 | G7: =IFERROR(Predpoklady!$C$50/D7,"—") -> 125.68661
A8: =A7+0.05 -> 0.2 | B8: =Naklad_run!$B$10*(1-$A8)*Naklad_volani!$F$14 -> 0.015579829 | C8: =B8/Predpoklady!$C$15 -> 0.014425768 | D8: =Naklad_run!$B$10*(1-$A8)*Naklad_volani!$F$15 -> 0.046739488 | E8: =D8/Predpoklady!$C$15 -> 0.043277304 | F8: =IFERROR(Predpoklady!$C$50/B8,"—") -> 400.62608 | G8: =IFERROR(Predpoklady!$C$50/D8,"—") -> 133.54203
A9: =A8+0.05 -> 0.25 | B9: =Naklad_run!$B$10*(1-$A9)*Naklad_volani!$F$14 -> 0.01460609 | C9: =B9/Predpoklady!$C$15 -> 0.013524157 | D9: =Naklad_run!$B$10*(1-$A9)*Naklad_volani!$F$15 -> 0.04381827 | E9: =D9/Predpoklady!$C$15 -> 0.040572472 | F9: =IFERROR(Predpoklady!$C$50/B9,"—") -> 427.33448 | G9: =IFERROR(Predpoklady!$C$50/D9,"—") -> 142.44483
A10: =A9+0.05 -> 0.3 | B10: =Naklad_run!$B$10*(1-$A10)*Naklad_volani!$F$14 -> 0.013632351 | C10: =B10/Predpoklady!$C$15 -> 0.012622547 | D10: =Naklad_run!$B$10*(1-$A10)*Naklad_volani!$F$15 -> 0.040897052 | E10: =D10/Predpoklady!$C$15 -> 0.037867641 | F10: =IFERROR(Predpoklady!$C$50/B10,"—") -> 457.85837 | G10: =IFERROR(Predpoklady!$C$50/D10,"—") -> 152.61946
A11: =A10+0.05 -> 0.35 | B11: =Naklad_run!$B$10*(1-$A11)*Naklad_volani!$F$14 -> 0.012658611 | C11: =B11/Predpoklady!$C$15 -> 0.011720936 | D11: =Naklad_run!$B$10*(1-$A11)*Naklad_volani!$F$15 -> 0.037975834 | E11: =D11/Predpoklady!$C$15 -> 0.035162809 | F11: =IFERROR(Predpoklady!$C$50/B11,"—") -> 493.07825 | G11: =IFERROR(Predpoklady!$C$50/D11,"—") -> 164.35942
A12: =A11+0.05 -> 0.4 | B12: =Naklad_run!$B$10*(1-$A12)*Naklad_volani!$F$14 -> 0.011684872 | C12: =B12/Predpoklady!$C$15 -> 0.010819326 | D12: =Naklad_run!$B$10*(1-$A12)*Naklad_volani!$F$15 -> 0.035054616 | E12: =D12/Predpoklady!$C$15 -> 0.032457978 | F12: =IFERROR(Predpoklady!$C$50/B12,"—") -> 534.1681 | G12: =IFERROR(Predpoklady!$C$50/D12,"—") -> 178.05603
A13: =A12+0.05 -> 0.45 | B13: =Naklad_run!$B$10*(1-$A13)*Naklad_volani!$F$14 -> 0.010711133 | C13: =B13/Predpoklady!$C$15 -> 0.0099177155 | D13: =Naklad_run!$B$10*(1-$A13)*Naklad_volani!$F$15 -> 0.032133398 | E13: =D13/Predpoklady!$C$15 -> 0.029753146 | F13: =IFERROR(Predpoklady!$C$50/B13,"—") -> 582.72884 | G13: =IFERROR(Predpoklady!$C$50/D13,"—") -> 194.24295
A14: =A13+0.05 -> 0.5 | B14: =Naklad_run!$B$10*(1-$A14)*Naklad_volani!$F$14 -> 0.0097373934 | C14: =B14/Predpoklady!$C$15 -> 0.009016105 | D14: =Naklad_run!$B$10*(1-$A14)*Naklad_volani!$F$15 -> 0.02921218 | E14: =D14/Predpoklady!$C$15 -> 0.027048315 | F14: =IFERROR(Predpoklady!$C$50/B14,"—") -> 641.00172 | G14: =IFERROR(Predpoklady!$C$50/D14,"—") -> 213.66724
A15: =A14+0.05 -> 0.55 | B15: =Naklad_run!$B$10*(1-$A15)*Naklad_volani!$F$14 -> 0.0087636541 | C15: =B15/Predpoklady!$C$15 -> 0.0081144945 | D15: =Naklad_run!$B$10*(1-$A15)*Naklad_volani!$F$15 -> 0.026290962 | E15: =D15/Predpoklady!$C$15 -> 0.024343483 | F15: =IFERROR(Predpoklady!$C$50/B15,"—") -> 712.22414 | G15: =IFERROR(Predpoklady!$C$50/D15,"—") -> 237.40805
A16: =A15+0.05 -> 0.6 | B16: =Naklad_run!$B$10*(1-$A16)*Naklad_volani!$F$14 -> 0.0077899147 | C16: =B16/Predpoklady!$C$15 -> 0.007212884 | D16: =Naklad_run!$B$10*(1-$A16)*Naklad_volani!$F$15 -> 0.023369744 | E16: =D16/Predpoklady!$C$15 -> 0.021638652 | F16: =IFERROR(Predpoklady!$C$50/B16,"—") -> 801.25215 | G16: =IFERROR(Predpoklady!$C$50/D16,"—") -> 267.08405
... A23: =A22+0.05 -> 0.95 | B23: =Naklad_run!$B$10*(1-$A23)*Naklad_volani!$F$14 -> 0.00097373934 | C23: =B23/Predpoklady!$C$15 -> 0.0009016105 | D23: =Naklad_run!$B$10*(1-$A23)*Naklad_volani!$F$15 -> 0.002921218 | E23: =D23/Predpoklady!$C$15 -> 0.0027048315 | F23: =IFERROR(Predpoklady!$C$50/B23,"—") -> 6410.0172 | G23: =IFERROR(Predpoklady!$C$50/D23,"—") -> 2136.6724

Sheet Break_even
A1: Break-even proti ceně 9,99 € (§8.2)
A2: Break-even = čistý příjem na licenci (Predpoklady!C50) / náklad na run bez cache. Hodiny hry = break-even × délka runu [P-2 doplňkové, 37,5 min] / 60.
A4: Model / režim | B4: Volání / run (efektivní) | C4: $ / volání | D4: $ / run (h = 0) | E4: Break-even (runů) | F4: ≈ hodin hry
A5: Opus 5, všechny uzly | B5: =Naklad_run!$B$10 -> 7.7868 | C5: =Naklad_volani!$F$17 -> 0.012505 | D5: =B5*C5 -> 0.097373934 | E5: =IFERROR(Predpoklady!$C$50/D5,"nekonečno") -> 64.100172 | F5: =IFERROR(E5*Predpoklady!$C$56/60,"—") -> 40.062608
A6: Sonnet 5 std, všechny uzly | B6: =Naklad_run!$B$10 -> 7.7868 | C6: =Naklad_volani!$F$15 -> 0.007503 | D6: =B6*C6 -> 0.05842436 | E6: =IFERROR(Predpoklady!$C$50/D6,"nekonečno") -> 106.83362 | F6: =IFERROR(E6*Predpoklady!$C$56/60,"—") -> 66.771013
A7: Sonnet 5 std + prompt cache (§5) | B7: =Naklad_run!$B$10 -> 7.7868 | C7: =Predpoklady!$C$54 -> 0.00495 | D7: =B7*C7 -> 0.03854466 | E7: =IFERROR(Predpoklady!$C$50/D7,"nekonečno") -> 161.93387 | F7: =IFERROR(E7*Predpoklady!$C$56/60,"—") -> 101.20867
A8: Haiku 4.5, všechny uzly | B8: =Naklad_run!$B$10 -> 7.7868 | C8: =Naklad_volani!$F$14 -> 0.002501 | D8: =B8*C8 -> 0.019474787 | E8: =IFERROR(Predpoklady!$C$50/D8,"nekonečno") -> 320.50086 | F8: =IFERROR(E8*Predpoklady!$C$56/60,"—") -> 200.31304
A9: Haiku 4.5, jen finálové uzly (§9c) | B9: =Naklad_run!$B$11 -> 3.1518 | C9: =Naklad_volani!$F$14 -> 0.002501 | D9: =B9*C9 -> 0.0078826518 | E9: =IFERROR(Predpoklady!$C$50/D9,"nekonečno") -> 791.82566 | F9: =IFERROR(E9*Predpoklady!$C$56/60,"—") -> 494.89104
A10: třída Flash-Lite, všechny uzly | B10: =Naklad_run!$B$10 -> 7.7868 | C10: =Naklad_volani!$F$18 -> 0.0002294 | D10: =B10*C10 -> 0.0017862919 | E10: =IFERROR(Predpoklady!$C$50/D10,"nekonečno") -> 3494.2138 | F10: =IFERROR(E10*Predpoklady!$C$56/60,"—") -> 2183.8837
A11: jen fallbacky (bez LLM) | B11: 0 | C11: 0 | D11: =B11*C11 -> 0 | E11: =IFERROR(Predpoklady!$C$50/D11,"nekonečno") -> nekonečno | F11: =IFERROR(E11*Predpoklady!$C$56/60,"—") -> —
A13: Run = 8–9 uzlů ≈ 35–40 min [odhad]. Model počítá se středem 37,5 min (Predpoklady!C56).

Sheet Naklad_hrace
A1: Náklad na hráče podle intenzity [P-12] (§8.3)
A2: Sloupce s cache používají P-13 z listu Predpoklady — hlavička se přepíše sama. Červeně = náklad překročil čistý příjem z licence (ztrátový hráč).
A4: Typ hráče | B4: Runů | C4: Haiku 4.5 · h = 0 % ($) | D4: % čistého příjmu | E4: ="Haiku 4.5 · h = "&TEXT(Predpoklady!$C$17,"0%")&" ($)" -> Haiku 4.5 · h = 60% ($) | F4: % čistého příjmu | G4: Sonnet 5 std · h = 0 % ($) | H4: % čistého příjmu | I4: ="Sonnet 5 std · h = "&TEXT(Predpoklady!$C$17,"0%")&" ($)" -> Sonnet 5 std · h = 60% ($) | J4: % čistého příjmu
A5: medián | B5: =Predpoklady!$B$36 -> 6 | C5: =$B5*Naklad_run!$B$10*Naklad_volani!$F$14 -> 0.11684872 | D5: =C5/Predpoklady!$C$50 -> 0.018720698 | E5: =$B5*Naklad_run!$B$10*(1-Predpoklady!$C$17)*Naklad_volani!$F$14 -> 0.046739488 | F5: =E5/Predpoklady!$C$50 -> 0.0074882794 | G5: =$B5*Naklad_run!$B$10*Naklad_volani!$F$15 -> 0.35054616 | H5: =G5/Predpoklady!$C$50 -> 0.056162095 | I5: =$B5*Naklad_run!$B$10*(1-Predpoklady!$C$17)*Naklad_volani!$F$15 -> 0.14021846 | J5: =I5/Predpoklady!$C$50 -> 0.022464838
A6: heavy | B6: =Predpoklady!$B$37 -> 100 | C6: =$B6*Naklad_run!$B$10*Naklad_volani!$F$14 -> 1.9474787 | D6: =C6/Predpoklady!$C$50 -> 0.31201164 | E6: =$B6*Naklad_run!$B$10*(1-Predpoklady!$C$17)*Naklad_volani!$F$14 -> 0.77899147 | F6: =E6/Predpoklady!$C$50 -> 0.12480466 | G6: =$B6*Naklad_run!$B$10*Naklad_volani!$F$15 -> 5.842436 | H6: =G6/Predpoklady!$C$50 -> 0.93603492 | I6: =$B6*Naklad_run!$B$10*(1-Predpoklady!$C$17)*Naklad_volani!$F$15 -> 2.3369744 | J6: =I6/Predpoklady!$C$50 -> 0.37441397
A7: extrém | B7: =Predpoklady!$B$38 -> 500 | C7: =$B7*Naklad_run!$B$10*Naklad_volani!$F$14 -> 9.7373934 | D7: =C7/Predpoklady!$C$50 -> 1.5600582 | E7: =$B7*Naklad_run!$B$10*(1-Predpoklady!$C$17)*Naklad_volani!$F$14 -> 3.8949574 | F7: =E7/Predpoklady!$C$50 -> 0.62402328 | G7: =$B7*Naklad_run!$B$10*Naklad_volani!$F$15 -> 29.21218 | H7: =G7/Predpoklady!$C$50 -> 4.6801746 | I7: =$B7*Naklad_run!$B$10*(1-Predpoklady!$C$17)*Naklad_volani!$F$15 -> 11.684872 | J7: =I7/Predpoklady!$C$50 -> 1.8720698
A8: populační průměr | B8: =Predpoklady!$B$39 -> 19.8 | C8: =$B8*Naklad_run!$B$10*Naklad_volani!$F$14 -> 0.38560078 | D8: =C8/Predpoklady!$C$50 -> 0.061778305 | E8: =$B8*Naklad_run!$B$10*(1-Predpoklady!$C$17)*Naklad_volani!$F$14 -> 0.15424031 | F8: =E8/Predpoklady!$C$50 -> 0.024711322 | G8: =$B8*Naklad_run!$B$10*Naklad_volani!$F$15 -> 1.1568023 | H8: =G8/Predpoklady!$C$50 -> 0.18533492 | I8: =$B8*Naklad_run!$B$10*(1-Predpoklady!$C$17)*Naklad_volani!$F$15 -> 0.46272093 | J8: =I8/Predpoklady!$C$50 -> 0.074133966
A10: Nález F: ekonomické riziko není v průměru, je v ocasu. Populační průměr je i na Sonnetu 5 pod 19 % čistého příjmu; ztrátový je výhradně extrémní hráč (~5 % populace), kterého z definice řeší fair-use strop.

Sheet Scenare
A1: Scénáře — hlavní výstupní tabulka (§9)
A2: Sólo run [P-7, 1 hráč]. $/hráč počítáno na populační průměr 19,8 runu [P-12]. Marže proti čistému příjmu $6,24 na licenci. Verdikt je text z §11, ne vzorec.
A4: Varianta | B4: Volání / run (efektivní) | C4: $ / volání | D4: $ / run | E4: $ / hráč (h = 0) | F4: ="$ / hráč (h = "&TEXT(Predpoklady!$C$17,"0%")&")" -> $ / hráč (h = 60%) | G4: ="Marže (h = "&TEXT(Predpoklady!$C$17,"0%")&")" -> Marže (h = 60%) | H4: Break-even (runů) | I4: Verdikt | J4: Poznámka (§9, §11)
A5: (a) plné LLM — Haiku 4.5, všechny uzly | B5: =Naklad_run!$B$10 -> 7.7868 | C5: =Naklad_volani!$F$14 -> 0.002501 | D5: =B5*C5 -> 0.019474787 | E5: =D5*Predpoklady!$B$39 -> 0.38560078 | F5: =D5*(1-Predpoklady!$C$17)*Predpoklady!$B$39 -> 0.15424031 | G5: =1-F5/Predpoklady!$C$50 -> 0.97528868 | H5: =IFERROR(Predpoklady!$C$50/D5,"nekonečno") -> 320.50086 | I5: udržitelné | J5: break-even 320 runů (~200 h); populační náklad 2,5–6,2 % čistého příjmu
A6: (b) plné LLM — Sonnet 5 std, všechny uzly | B6: =Naklad_run!$B$10 -> 7.7868 | C6: =Naklad_volani!$F$15 -> 0.007503 | D6: =B6*C6 -> 0.05842436 | E6: =D6*Predpoklady!$B$39 -> 1.1568023 | F6: =D6*(1-Predpoklady!$C$17)*Predpoklady!$B$39 -> 0.46272093 | G6: =1-F6/Predpoklady!$C$50 -> 0.92586603 | H6: =IFERROR(Predpoklady!$C$50/D6,"nekonečno") -> 106.83362 | I6: rizikové | J6: udržitelné v průměru, ale fair-use strop zafunguje po 26–64 runech → byl by viditelný (nález G)
A7: (b') Sonnet 5 std + prompt cache (§5) | B7: =Naklad_run!$B$10 -> 7.7868 | C7: =Predpoklady!$C$54 -> 0.00495 | D7: =B7*C7 -> 0.03854466 | E7: =D7*Predpoklady!$B$39 -> 0.76318427 | F7: =D7*(1-Predpoklady!$C$17)*Predpoklady!$B$39 -> 0.30527371 | G7: =1-F7/Predpoklady!$C$50 -> 0.95109115 | H7: =IFERROR(Predpoklady!$C$50/D7,"nekonečno") -> 161.93387 | I7: udržitelné | J7: nález D stojí 52 tokenů few-shotu a sráží cenu volání o 40 %; poměr k Haiku klesá z 3,0× na 2,0×
A8: (c) hybrid — Haiku 4.5 jen na finálových uzlech | B8: =Naklad_run!$B$11 -> 3.1518 | C8: =Naklad_volani!$F$14 -> 0.002501 | D8: =B8*C8 -> 0.0078826518 | E8: =D8*Predpoklady!$B$39 -> 0.15607651 | F8: =D8*(1-Predpoklady!$C$17)*Predpoklady!$B$39 -> 0.062430602 | G8: =1-F8/Predpoklady!$C$50 -> 0.9899978 | H8: =IFERROR(Predpoklady!$C$50/D8,"nekonečno") -> 791.82566 | I8: udržitelné | J8: nejlevnější varianta s LLM; break-even 792 runů (~500 h)
A9: (c') hybrid — Sonnet 5 std jen na finálových uzlech | B9: =Naklad_run!$B$11 -> 3.1518 | C9: =Naklad_volani!$F$15 -> 0.007503 | D9: =B9*C9 -> 0.023647955 | E9: =D9*Predpoklady!$B$39 -> 0.46822952 | F9: =D9*(1-Predpoklady!$C$17)*Predpoklady!$B$39 -> 0.18729181 | G9: =1-F9/Predpoklady!$C$50 -> 0.96999339 | H9: =IFERROR(Predpoklady!$C$50/D9,"nekonečno") -> 263.94189 | I9: udržitelné s rezervou | J9: DOPORUČENO §11: 3× lepší model za +21 % proti (a), míří na uzly, kde run vrcholí
A10: (d) žádné LLM — jen fallbacky | B10: 0 | C10: 0 | D10: =B10*C10 -> 0 | E10: =D10*Predpoklady!$B$39 -> 0 | F10: =D10*(1-Predpoklady!$C$17)*Predpoklady!$B$39 -> 0 | G10: =1-F10/Predpoklady!$C$50 -> 1 | H10: =IFERROR(Predpoklady!$C$50/D10,"nekonečno") -> nekonečno | I10: udržitelné | J10: finančně nulové, ale fallback sada má 28 šablon → opakování kostry uvnitř jednoho runu 52–62 % (§9.1)

Sheet Fair_use
A1: Fair-use strop na útratu za API (§8.4)
A3: Strop útraty na licenci ($) | B3: =Predpoklady!$C$57 -> 1.5
A4: Podíl čistého příjmu z licence | B4: =B3/Predpoklady!$C$50 -> 0.24031968
A5: Hodnotu stropu edituj v Predpoklady!C57 (modře, žlutě podbarveno) — tento list je jen odkaz, aby model měl jediný zdroj pravdy.
A6: Strop na POČET RUNŮ je špatná metrika: s dozrávající cache se mění, co si můžeme dovolit. Strop na útratu se sám uvolňuje a nepotřebuje přeladit při změně modelu ani ceníku.
A8: Režim | B8: Runů do stropu · h = 0 % | C8: ="Runů do stropu · h = "&TEXT(Predpoklady!$C$17,"0%") -> Runů do stropu · h = 60% | D8: Viditelný pro hráče?
A9: Haiku 4.5, všechny uzly | B9: =IFERROR($B$3/Scenare!$D$5,"nekonečno") -> 77.022666 | C9: =IFERROR($B$3/(Scenare!$D$5*(1-Predpoklady!$C$17)),"nekonečno") -> 192.55667 | D9: ne — strop zafunguje daleko za mediánem (6 runů) i za heavy hráčem (100)
A10: Haiku 4.5, jen finálové uzly | B10: =IFERROR($B$3/Scenare!$D$8,"nekonečno") -> 190.29129 | C10: =IFERROR($B$3/(Scenare!$D$8*(1-Predpoklady!$C$17)),"nekonečno") -> 475.72823 | D10: ne — prakticky nezafunguje
A11: Sonnet 5 std, všechny uzly | B11: =IFERROR($B$3/Scenare!$D$6,"nekonečno") -> 25.674222 | C11: =IFERROR($B$3/(Scenare!$D$6*(1-Predpoklady!$C$17)),"nekonečno") -> 64.185555 | D11: ANO — nález G: zafunguje u každého trochu zaujatého hráče, porušuje zadání „tichý strop“
A12: Sonnet 5 std + prompt cache (§5) | B12: =IFERROR($B$3/Scenare!$D$7,"nekonečno") -> 38.915897 | C12: =IFERROR($B$3/(Scenare!$D$7*(1-Predpoklady!$C$17)),"nekonečno") -> 97.289741 | D12: hraničně — u zaujatého hráče už viditelný
A13: Sonnet 5 std, jen finálové uzly | B13: =IFERROR($B$3/Scenare!$D$9,"nekonečno") -> 63.430431 | C13: =IFERROR($B$3/(Scenare!$D$9*(1-Predpoklady!$C$17)),"nekonečno") -> 158.57608 | D13: ne — doporučená konfigurace §11
A15: Po vyčerpání stropu jede hra čistě z cache a fallbacků — což je dle D40 plnohodnotný primární obsah, ne degradace.

Sheet Predgenerovani
A1: Předgenerování cache dávkovým API (§7)
A2: Batch API má −50 % a latenci až 24 h → pro živé volání nepoužitelné (hra nikdy nečeká na síť), pro naplnění cache před launchem ideální. Cena = objem × cena za volání × násobek batch (Predpoklady!C55).
A4: Objem předgenerovaných protokolů | B4: Haiku 4.5 batch ($) | C4: Sonnet 5 std batch ($)
A5: 50000 | B5: =$A5*Naklad_volani!$F$14*Predpoklady!$C$55 -> 62.525 | C5: =$A5*Naklad_volani!$F$15*Predpoklady!$C$55 -> 187.575
A6: 200000 | B6: =$A6*Naklad_volani!$F$14*Predpoklady!$C$55 -> 250.1 | C6: =$A6*Naklad_volani!$F$15*Predpoklady!$C$55 -> 750.3
A7: 1000000 | B7: =$A7*Naklad_volani!$F$14*Predpoklady!$C$55 -> 1250.5 | C7: =$A7*Naklad_volani!$F$15*Predpoklady!$C$55 -> 3751.5
A9: Kolik prodaných kopií to zaplatí (čistý příjem na licenci, Predpoklady!C50)
A10: Objem | B10: Kopií (Haiku 4.5) | C10: Kopií (Sonnet 5 std)
A11: =A5 -> 50000 | B11: =B5/Predpoklady!$C$50 -> 10.017326 | C11: =C5/Predpoklady!$C$50 -> 30.051977
A12: =A6 -> 200000 | B12: =B6/Predpoklady!$C$50 -> 40.069302 | C12: =C6/Predpoklady!$C$50 -> 120.20791
A13: =A7 -> 1000000 | B13: =B7/Predpoklady!$C$50 -> 200.34651 | C13: =C7/Predpoklady!$C$50 -> 601.03953
A15: Při klíčovém prostoru varianty B (3,6 × 10^5) pokryje 200 000 předgenerovaných protokolů hlavu distribuce → startovní hit-rate 50–65 % od prvního dne místo 0 %.
A16: Vedlejší zisky: odpadá cold-start, cache hit = nulová latence, obsah lze projet regresní baterií humor-testera před hráčem, free demo [P-15] může jet z téže databáze.
A17: Pozn.: report §7 uvádí orientačně „1 prodaná kopie na 800 protokolů“; model počítá poměr přímo z ceníku a vychází příznivěji (viz řádky 11–13).

Sheet Legenda
A1: Legenda a pravidla používání modelu
A3: Položka | B3: Význam
A4: Barevná konvence
A5: modrý text | B5: zadaná (hardcodovaná) hodnota — vstup nebo scénářová páka. Vyskytuje se pouze na listech Predpoklady a Cenik.
A6: černý text | B6: vzorec počítaný v rámci téhož listu.
A7: zelený text | B7: odkaz na jiný list téhož sešitu.
A8: žluté podbarvení | B8: klíčová páka — hodnota, která nejvíc mění výsledek: P-2, P-7, P-8, P-12, P-13, cena licence, fair-use strop.
A9: červené číslo | B9: podmíněné formátování na listu Naklad_hrace: náklad překročil 100 % čistého příjmu z licence (ztrátový hráč).
A11: Kde se edituje
A12: Predpoklady | B12: JEDINÉ místo k editaci vstupů. Všechny ostatní listy na něj odkazují vzorci; žádná hodnota se nikde neopakuje natvrdo.
A13: Cenik | B13: druhý a poslední list se zadanými hodnotami — jednotkové ceny modelů. POSKYTOVATEL-SPECIFICKÝ: při změně poskytovatele se mění pouze tento list.
A14: Nejrychlejší páky | B14: P-13 (cache hit-rate, Predpoklady!C17), P-2 (tokenizer, C6), P-8 (zmařená volání, C12), fair-use strop (C57).
A16: Obsah listů
A17: Predpoklady | B17: vstupy P-1 až P-15, detail P-7 a P-12, příjmová strana licence, doplňkové parametry (§5, §7, §8.2, §8.4).
A18: Cenik | B18: jednotkové ceny modelů a poskytovatel-specifické poznámky (min. cachovatelný prefix, cache násobky).
A19: Naklad_volani | B19: skladba promptu ve znacích a tokenech (§2.1) a cena za jedno volání pro každý model (§2.2).
A20: Citlivost_tokenizer | B20: cena volání při 2,2 / 2,5 / 3,0 znaku na token (§3).
A21: Naklad_run | B21: volání na run 1p–4p, efektivní volání včetně zmařených, matice nákladu na run (§4).
A22: Cache_krivka | B22: náklad na sólo run a break-even podle cache hit-rate 0–95 % včetně grafu (§6.1).
A23: Break_even | B23: break-even v runech a hodinách hry pro jednotlivé režimy (§8.2).
A24: Naklad_hrace | B24: náklad na hráče podle intenzity hraní jako absolutní částka i % čistého příjmu (§8.3).
A25: Scenare | B25: hlavní výstupní tabulka — varianty (a) až (d) s marží, break-even a verdiktem (§9, §11).
A26: Fair_use | B26: po kolika runech zafunguje strop $1,50 na licenci a zda to hráč uvidí (§8.4).
A27: Predgenerovani | B27: cena naplnění cache dávkovým API a kolik prodaných kopií ji zaplatí (§7).
A29: Metodické poznámky
A30: Zaokrouhlení tokenů | B30: Tokeny se počítají jako ROUND(znaků / P-2; 0), protože token je celé číslo. Report §3 v citlivostní tabulce místy počítá s nezaokrouhlenými tokeny — odtud odchylka do 0,1 % u řádků 2,2 a 3,0.
A31: Zmařená volání | B31: Efektivní volání = změřená volání × (1 + P-8). Zmařené volání se platí celé.
A32: Přesnost break-even | B32: Model počítá z přesných 7,7868 efektivního volání, report §8.2 z zaokrouhlených 7,79 — proto model ukazuje break-even Haiku 320,5 runu tam, kde report píše 320. Rozdíl je 0,2 %, nikoli chyba.
A33: Sólo vs. hot-seat | B33: Model je konzervativně stavěn na sólo run. Hot-seat 4 hráčů jede z jedné licence, ale generuje o 15 % víc volání — je ekonomicky horší.
A34: Verdikty | B34: Sloupec Verdikt na listu Scenare je text převzatý z §11 reportu, ne vzorec — je to úsudek, ne výpočet.
A36: Původ a odpovědnost
A37: Zdroj všech čísel | B37: technika/llm-rozpocet-2026-07-28.md — kanonický report, na který se model odkazuje po sekcích (§n).
A38: Autor | B38: operations-economics
A39: Datum | B39: 46231
A40: Upozornění | B40: Ceník je POSKYTOVATEL-SPECIFICKÝ. Při změně poskytovatele se mění list Cenik (jednotkové ceny), a spolu s ním je potřeba přehodnotit i minimální cachovatelný prefix, násobky cache read/write, batch slevu a tokenizaci (±20 %) — viz §10 reportu.
